<?xml version="1.0"?>
<robot name="archer_d6y">
    <link name="base_link">
        <inertial>
            <origin xyz="-0.001 0.0318 0" rpy="0 0 0" />
            <mass value="0.687" />
            <inertia ixx="0.0005" ixy="0" ixz="0" iyy="0.0007" iyz="0" izz="0.0006" />
        </inertial>
        <visual>
            <origin xyz="0 0 0" rpy="0 0 0" />
            <geometry>
                <mesh filename="arm_base_link.STL" />
            </geometry>
            <material name="">
                <color rgba="1 1 1 1" />
            </material>
        </visual>
        <collision>
            <origin xyz="0 0 0" rpy="0 0 0" />
            <geometry>
                <mesh filename="arm_base_link.STL" />
            </geometry>
        </collision>
    </link>
  
    <link name="link_1">
        <inertial>
            <origin xyz="0.008 0.0878 0.0023" rpy="0 0 0" />
            <mass value="0.2154" />
            <inertia ixx="0.0003" ixy="0" ixz="0" iyy="0.0003" iyz="0" izz="0.0002" />
        </inertial>
        <visual>
            <origin xyz="0 0 0" rpy="0 0 0" />
            <geometry>
                <mesh filename="arm_link_1.STL" />
            </geometry>
            <material name="">
                <color rgba="0.925490196078431 0.925490196078431 0.925490196078431 1" />
            </material>
        </visual>
        <collision>
            <origin xyz="0 0 0" rpy="0 0 0" />
            <geometry>
                <mesh filename="arm_link_1.STL" />
            </geometry>
        </collision>
    </link>
    <joint name="joint_1" type="revolute">
        <origin xyz="0 0 0.0665" rpy="0 0 0" />
        <parent link="base_link" />
        <child link="link_1" />
        <axis xyz="0 0 1" />
        <limit effort="40.0" lower="-2.7" upper="2.7" velocity="2.0"/>
        <dynamics damping="1.0" friction="0.0"/>
    </joint>

    <link name="link_2">
        <inertial>
            <origin xyz="0.0201 0.2429 0.0038" rpy="0 0 0" />
            <mass value="1.3123" />
            <inertia ixx="0.0185" ixy="0" ixz="0" iyy="0.0007" iyz="-0.0001" izz="0.0182" />
        </inertial>
        <visual>
            <origin xyz="0 0 0" rpy="0 0 0" />
            <geometry>
                <mesh filename="arm_link_2.STL" />
            </geometry>
            <material name="">
                <color rgba="1 1 1 1" />
            </material>
        </visual>
        <collision>
            <origin xyz="0 0 0" rpy="0 0 0" />
            <geometry>
                <mesh filename="arm_link_2.STL" />
            </geometry>
        </collision>
    </link>
    <joint name="joint_2" type="revolute">
        <origin xyz="0.02 0 0.045" rpy="0 0 0" />
        <parent link="link_1" />
        <child link="link_2" />
        <axis xyz="0 1 0" />
        <limit effort="40.0" lower="-1.57" upper="2.09" velocity="2.0"/>
        <dynamics damping="1.0" friction="0.0"/>
    </joint>

    <link name="link_3">
        <inertial>
            <origin xyz="-0.031 0.52 -0.0009" rpy="0 0 0" />
            <mass value="1.1083" />
            <inertia ixx="0.0113" ixy="0.0014" ixz="0.0001" iyy="0.0016" iyz="-0.0006" izz="0.0111" />
        </inertial>
        <visual>
            <origin xyz="0 0 0" rpy="0 0 0" />
            <geometry>
                <mesh filename="arm_link_3.STL" />
            </geometry>
            <material name="">
                <color rgba="1 1 1 1" />
            </material>
        </visual>
        <collision>
            <origin xyz="0 0 0" rpy="0 0 0" />
            <geometry>
                <mesh filename="arm_link_3.STL" />
            </geometry>
        </collision>
    </link>
    <joint name="joint_3" type="revolute">
        <origin xyz="0 0 0.264" rpy="0 0 0" />
        <parent link="link_2" />
        <child link="link_3" />
        <axis xyz="0 1 0" />
        <limit effort="40.0" lower="0" upper="3.14" velocity="2.0"/>
        <dynamics damping="1.0" friction="0.0"/>
    </joint>

    <link name="link_4">
        <inertial>
            <origin xyz="-0.0998 0.6777 0.001" rpy="0 0 0" />
            <mass value="0.5398" />
            <inertia ixx="0.0008" ixy="0.0003" ixz="0" iyy="0.0008" iyz="0" izz="0.001" />
        </inertial>
        <visual>
            <origin xyz="0 0 0" rpy="0 0 0" />
            <geometry>
                <mesh filename="arm_link_4.STL" />
            </geometry>
            <material name="">
                <color rgba="0.792156862745098 0.792156862745098 0.792156862745098 1" />
            </material>
        </visual>
        <collision>
            <origin xyz="0 0 0" rpy="0 0 0" />
            <geometry>
                <mesh filename="arm_link_4.STL" />
            </geometry>
        </collision>
    </link>
    <joint name="joint_4" type="revolute">
        <origin xyz="-0.06 0 0.245" rpy="0 0 0" />
        <parent link="link_3" />
        <child link="link_4" />
        <axis xyz="0 1 0" />
        <limit effort="40.0" lower="-1.57" upper="1.57" velocity="2.0"/>
        <dynamics damping="1.0" friction="0.0"/>
    </joint>

    <link name="link_5">
        <inertial>
            <origin xyz="-0.0442 0.6936 -0.0001" rpy="0 0 0" />
            <mass value="0.3984" />
            <inertia ixx="0.0002" ixy="0" ixz="0" iyy="0.0002" iyz="0" izz="0.0003" />
        </inertial>
        <visual>
            <origin xyz="0 0 0" rpy="0 0 0" />
            <geometry>
                <mesh filename="arm_link_5.STL" />
            </geometry>
            <material name="">
                <color rgba="0.898039215686275 0.917647058823529 0.929411764705882 1" />
            </material>
        </visual>
        <collision>
            <origin xyz="0 0 0" rpy="0 0 0" />
            <geometry>
                <mesh filename="arm_link_5.STL" />
            </geometry>
        </collision>
    </link>
    <joint name="joint_5" type="revolute">
        <origin xyz="-0.0553 0 0.07025" rpy="0 0 0" />
        <parent link="link_4" />
        <child link="link_5" />
        <axis xyz="-1 0 0" />
        <limit effort="40.0" lower="-1.57" upper="1.57" velocity="2.0"/>
        <dynamics damping="1.0" friction="0.0"/>
    </joint>

    <link name="picker_base_link">
        <inertial>
            <origin xyz="-0.00005520 1.2341E-05 0.03296193" rpy="0 0 0" />
            <mass value="0.25641368" />
            <inertia ixx="4.6351E-04" ixy="-1.0E-08" ixz="-1.04E-06"
                     iyy="4.4525E-04" iyz="-5.00E-08" izz="1.0438E-04" />
        </inertial>
        <visual>
            <origin rpy="0 0 0" xyz="0 0 0" />
            <geometry>
                <mesh filename="picker_base_link.STL" />
            </geometry>
            <material name="">
                <color rgba="0.89804 0.91765 0.92941 1" />
            </material>
        </visual>
        <collision>
            <origin xyz="0 0 0.005" rpy="0 0 0" />
            <geometry>
                <mesh filename="picker_base_link.STL" />
            </geometry>
        </collision>
    </link>
    <joint name="joint_6" type="revolute">
        <origin xyz="0.0547 0 0.02895" rpy="0 0 0" />
        <parent link="link_5" />
        <child link="picker_base_link" />
        <axis xyz="0 0 1" />
        <limit effort="40.0" lower="-1.57" upper="1.57" velocity="2.0"/>
        <dynamics damping="1.0" friction="0.0"/>
    </joint>
    
    <link name="picker_narrow1_link">
        <inertial>
            <origin xyz="0.0094685 0.0068806 6.5437E-05" rpy="0 0 0" />
            <mass value="0.025428" />
            <inertia ixx="1.9574E-06" ixy="-4.2911E-07" ixz="-3.7111E-11"
                     iyy="2.3919E-06" iyz="-3.008E-10" izz="1.5501E-06" />
        </inertial>
        <visual>
            <origin xyz="0 0 0" rpy="0 0 0" />
            <geometry>
                <mesh filename="picker_narrow1_link.STL" />
            </geometry>
            <material name="">
                <color rgba="0.75294 0.75294 0.75294 1" />
            </material>
        </visual>
        <collision>
            <origin xyz="0 0 0" rpy="0 0 0" />
            <geometry>
                <mesh filename="picker_narrow1_link.STL" />
            </geometry>
        </collision>
    </link>
    <joint name="picker_narrow1_joint" type="fixed">
        <origin xyz="0 -0.0195 0.0565" rpy="-2.9951 -1.5708 -0.15964" />
        <parent link="picker_base_link" />
        <child link="picker_narrow1_link" />
    </joint>

    <link name="picker_narrow2_link">
        <inertial>
            <origin xyz="0.0088027 -0.007035 1.6424E-05" rpy="0 0 0" />
            <mass value="0.0040132" />
            <inertia ixx="1.0307E-07" ixy="5.7851E-08" ixz="9.5801E-11"
                     iyy="1.1385E-07" iyz="-2.81E-11" izz="1.7009E-07" />
        </inertial>
        <visual>
            <origin xyz="0 0 0" rpy="0 0 0" />
            <geometry>
                <mesh filename="picker_narrow2_link.STL" />
            </geometry>
            <material name="">
                <color rgba="0.75294 0.75294 0.75294 1" />
            </material>
        </visual>
        <collision>
            <origin xyz="0 0 0" rpy="0 0 0" />
            <geometry>
                <mesh filename="picker_narrow2_link.STL" />
            </geometry>
        </collision>
    </link>
    <joint name="picker_narrow2_joint" type="fixed">
        <origin xyz="0.030852 0.018551 0" rpy="0 0 0" />
        <parent link="picker_narrow1_link" />
        <child link="picker_narrow2_link" />
    </joint>
    
    <link name="picker_narrow3_link">
        <inertial>
            <origin xyz="0.012508 -0.0079729 9.4339E-05" rpy="0 0 0" />
            <mass value="0.018029" />
            <inertia ixx="1.1403E-06" ixy="5.5159E-07" ixz="-4.0096E-13"
                     iyy="2.5704E-06" iyz="1.0951E-12" izz="2.3252E-06" />
        </inertial>
        <visual>
            <origin xyz="0 0 0" rpy="0 0 0" />
            <geometry>
                <mesh filename="picker_narrow3_link.STL" />
            </geometry>
            <material name="">
                <color rgba="0.75294 0.75294 0.75294 1" />
            </material>
        </visual>
        <collision>
            <origin xyz="0 0 0" rpy="0 0 0" />
            <geometry>
                <mesh filename="picker_narrow3_link.STL" />
            </geometry>
        </collision>
    </link>
    <joint name="picker_narrow3_joint" type="fixed">
        <origin xyz="0.018118 -0.01574 0" rpy="0 0 0" />
        <parent link="picker_narrow2_link" />
        <child link="picker_narrow3_link" />
    </joint>
    
    <link name="picker_narrow_loop_link">
        <inertial>
            <origin xyz="0.014869 -0.0036066 0.00029307" rpy="0 0 0" />
            <mass value="0.022591" />
            <inertia ixx="4.3916E-06" ixy="1.114E-07" ixz="-4.9655E-12"
                     iyy="4.737E-06" iyz="1.7121E-11" izz="6.0445E-07" />
        </inertial>
        <visual>
            <origin xyz="0 0 0" rpy="0 0 0" />
            <geometry>
                <mesh filename="picker_narrow_loop_link.STL" />
            </geometry>
            <material name="">
                <color rgba="0.75294 0.75294 0.75294 1" />
            </material>
        </visual>
        <collision>
            <origin xyz="0 0 0" rpy="0 0 0" />
            <geometry>
                <mesh filename="picker_narrow_loop_link.STL" />
            </geometry>
        </collision>
    </link>
    <joint name="picker_narrow_loop_joint" type="fixed">
        <origin xyz="0 -0.021633 0.07387" rpy="-2.9951 -1.5708 -0.15964" />
        <parent link="picker_base_link" />
        <child link="picker_narrow_loop_link" />
    </joint>

    <link name="picker_wide1_link">
        <inertial>
            <origin xyz="0.0095051 -0.0068479 6.8268E-05" rpy="0 0 0" />
            <mass value="0.025428" />
            <inertia ixx="1.9565E-06" ixy="4.2798E-07" ixz="2.3844E-10"
                     iyy="2.3928E-06" iyz="-1.4454E-10" izz="1.5501E-06" />
        </inertial>
        <visual>
            <origin xyz="0 0 0" rpy="0 0 0" />
            <geometry>
                <mesh filename="picker_wide1_link.STL" />
            </geometry>
            <material name="">
                <color rgba="0.75294 0.75294 0.75294 1" />
            </material>
        </visual>
        <collision>
            <origin xyz="0 0 0" rpy="0 0 0" />
            <geometry>
                <mesh filename="picker_wide1_link.STL" />
            </geometry>
        </collision>
    </link>
    <joint name="picker_wide1_joint" type="fixed">
        <origin xyz="0 0.0195 0.0565" rpy="-2.9951 -1.5708 -0.15964" />
        <parent link="picker_base_link" />
        <child link="picker_wide1_link" />
    </joint>

    <link name="picker_wide2_link">
        <inertial>
            <origin xyz="0.0088027 0.007035 -1.6424E-05" rpy="0 0 0" />
            <mass value="0.0040132" />
            <inertia ixx="1.0307E-07" ixy="-5.7851E-08" ixz="-9.58E-11"
                     iyy="1.1385E-07" iyz="-2.81E-11" izz="1.7009E-07" />
        </inertial>
        <visual>
            <origin xyz="0 0 0" rpy="0 0 0" />
            <geometry>
                <mesh filename="picker_wide2_link.STL" />
            </geometry>
            <material name="">
                <color rgba="0.75294 0.75294 0.75294 1" />
            </material>
        </visual>
        <collision>
            <origin xyz="0 0 0" rpy="0 0 0" />
            <geometry>
                <mesh filename="picker_wide2_link.STL" />
            </geometry>
        </collision>
    </link>
    <joint name="picker_wide2_joint" type="fixed">
        <origin xyz="0.030852 -0.018551 0" rpy="0 0 0" />
        <parent link="picker_wide1_link" />
        <child link="picker_wide2_link" />
    </joint>

    <link name="picker_wide3_link">
        <inertial>
            <origin xyz="0.016206 0.0094593 4.7668E-05" rpy="0 0 0" />
            <mass value="0.035835" />
            <inertia ixx="8.5056E-06" ixy="-1.1363E-06" ixz="-4.2908E-11"
                     iyy="1.1235E-05" iyz="-2.9251E-11" izz="4.6309E-06" />
        </inertial>
        <visual>
            <origin xyz="0 0 0" rpy="0 0 0" />
            <geometry>
                <mesh filename="picker_wide3_link.STL" />
            </geometry>
            <material name="">
                <color rgba="0.75294 0.75294 0.75294 1" />
            </material>
        </visual>
        <collision>
            <origin xyz="0 0 0" rpy="0 0 0" />
            <geometry>
                <mesh filename="picker_wide3_link.STL" />
            </geometry>
        </collision>
    </link>
    <joint name="picker_wide3_joint" type="fixed">
        <origin xyz="0.018118 0.01574 0" rpy="0 0 0" />
        <parent link="picker_wide2_link" />
        <child link="picker_wide3_link" />
    </joint>

    <link name="picker_wide_loop_link">
        <inertial>
            <origin xyz="0.016268 0.0040555 0.00030323" rpy="0 0 0" />
            <mass value="0.025142" />
            <inertia ixx="5.887E-06" ixy="-1.1234E-07" ixz="2.1954E-11"
                     iyy="6.236E-06" iyz="-9.473E-12" izz="6.2389E-07" />
        </inertial>
        <visual>
            <origin xyz="0 0 0" rpy="0 0 0" />
            <geometry>
                <mesh filename="picker_wide_loop_link.STL" />
            </geometry>
            <material name="">
                <color rgba="0.75294 0.75294 0.75294 1" />
            </material>
        </visual>
        <collision>
            <origin xyz="0 0 0" rpy="0 0 0" />
            <geometry>
                <mesh filename="picker_wide_loop_link.STL" />
            </geometry>
        </collision>
    </link>
    <joint name="picker_wide_loop_joint" type="fixed">
        <origin xyz="0 0.021633 0.07387" rpy="-2.9951 -1.5708 -0.15964" />
        <parent link="picker_base_link" />
        <child link="picker_wide_loop_link" />
    </joint>

</robot>